[2025-07-20T10:45:14.324+0000] {taskinstance.py:1956} INFO - Dependencies all met for dep_context=non-requeueable deps ti=<TaskInstance: retrain_model_dag.retrain_best_model manual__2025-07-20T10:44:58.674178+00:00 [queued]>
[2025-07-20T10:45:14.364+0000] {taskinstance.py:1956} INFO - Dependencies all met for dep_context=requeueable deps ti=<TaskInstance: retrain_model_dag.retrain_best_model manual__2025-07-20T10:44:58.674178+00:00 [queued]>
[2025-07-20T10:45:14.366+0000] {taskinstance.py:2170} INFO - Starting attempt 1 of 1
[2025-07-20T10:45:14.464+0000] {taskinstance.py:2191} INFO - Executing <Task(PythonOperator): retrain_best_model> on 2025-07-20 10:44:58.674178+00:00
[2025-07-20T10:45:14.492+0000] {standard_task_runner.py:60} INFO - Started process 127 to run task
[2025-07-20T10:45:14.508+0000] {standard_task_runner.py:87} INFO - Running: ['airflow', 'tasks', 'run', 'retrain_model_dag', 'retrain_best_model', 'manual__2025-07-20T10:44:58.674178+00:00', '--job-id', '61', '--raw', '--subdir', 'DAGS_FOLDER/retrain_model_dag.py', '--cfg-path', '/tmp/tmpt8uzn9im']
[2025-07-20T10:45:14.518+0000] {standard_task_runner.py:88} INFO - Job 61: Subtask retrain_best_model
[2025-07-20T10:45:14.770+0000] {task_command.py:423} INFO - Running <TaskInstance: retrain_model_dag.retrain_best_model manual__2025-07-20T10:44:58.674178+00:00 [running]> on host 2714c4a72725
[2025-07-20T10:45:15.078+0000] {taskinstance.py:2480} INFO - Exporting env vars: AIRFLOW_CTX_DAG_OWNER='airflow' AIRFLOW_CTX_DAG_ID='retrain_model_dag' AIRFLOW_CTX_TASK_ID='retrain_best_model' AIRFLOW_CTX_EXECUTION_DATE='2025-07-20T10:44:58.674178+00:00' AIRFLOW_CTX_TRY_NUMBER='1' AIRFLOW_CTX_DAG_RUN_ID='manual__2025-07-20T10:44:58.674178+00:00'
[2025-07-20T10:45:15.081+0000] {logging_mixin.py:188} INFO - üì¶ Starting retraining process
[2025-07-20T10:45:15.082+0000] {logging_mixin.py:188} INFO - üóÑÔ∏è Loading data...
[2025-07-20T10:45:15.277+0000] {logging_mixin.py:188} INFO - ‚öôÔ∏è Running full preprocessing...
[2025-07-20T10:45:16.130+0000] {logging_mixin.py:188} INFO - ‚úÇÔ∏è Splitting data...
[2025-07-20T10:45:16.200+0000] {logging_mixin.py:188} INFO - 
üß† Training model: LogisticRegression
[2025-07-20T10:45:17.897+0000] {logging_mixin.py:188} INFO - ‚úÖ Accuracy:  0.8176
[2025-07-20T10:45:17.911+0000] {logging_mixin.py:188} INFO - ‚úÖ Precision: 0.7622
[2025-07-20T10:45:17.912+0000] {logging_mixin.py:188} INFO - ‚úÖ Recall:    0.7654
[2025-07-20T10:45:17.913+0000] {logging_mixin.py:188} INFO - ‚úÖ F1-score:  0.7638
[2025-07-20T10:45:17.925+0000] {logging_mixin.py:188} INFO - ‚úÖ AUC-ROC:   0.8694
[2025-07-20T10:45:17.927+0000] {logging_mixin.py:188} INFO - 
üß† Training model: RandomForest
[2025-07-20T10:45:19.989+0000] {logging_mixin.py:188} INFO - ‚úÖ Accuracy:  0.8203
[2025-07-20T10:45:19.990+0000] {logging_mixin.py:188} INFO - ‚úÖ Precision: 0.7905
[2025-07-20T10:45:19.991+0000] {logging_mixin.py:188} INFO - ‚úÖ Recall:    0.7261
[2025-07-20T10:45:19.991+0000] {logging_mixin.py:188} INFO - ‚úÖ F1-score:  0.7570
[2025-07-20T10:45:19.992+0000] {logging_mixin.py:188} INFO - ‚úÖ AUC-ROC:   0.8854
[2025-07-20T10:45:19.992+0000] {logging_mixin.py:188} INFO - 
üß† Training model: XGBoost
[2025-07-20T10:45:30.567+0000] {logging_mixin.py:188} INFO - ‚úÖ Accuracy:  0.8193
[2025-07-20T10:45:30.568+0000] {logging_mixin.py:188} INFO - ‚úÖ Precision: 0.7838
[2025-07-20T10:45:30.568+0000] {logging_mixin.py:188} INFO - ‚úÖ Recall:    0.7331
[2025-07-20T10:45:30.569+0000] {logging_mixin.py:188} INFO - ‚úÖ F1-score:  0.7576
[2025-07-20T10:45:30.569+0000] {logging_mixin.py:188} INFO - ‚úÖ AUC-ROC:   0.8930
[2025-07-20T10:45:30.570+0000] {logging_mixin.py:188} INFO - 
üß† Training model: LightGBM
[2025-07-20T10:45:30.818+0000] {logging_mixin.py:188} INFO - ‚úÖ Accuracy:  0.8279
[2025-07-20T10:45:30.819+0000] {logging_mixin.py:188} INFO - ‚úÖ Precision: 0.7872
[2025-07-20T10:45:30.820+0000] {logging_mixin.py:188} INFO - ‚úÖ Recall:    0.7584
[2025-07-20T10:45:30.821+0000] {logging_mixin.py:188} INFO - ‚úÖ F1-score:  0.7725
[2025-07-20T10:45:30.822+0000] {logging_mixin.py:188} INFO - ‚úÖ AUC-ROC:   0.8967
[2025-07-20T10:45:30.823+0000] {logging_mixin.py:188} INFO - 
üß† Training model: DecisionTree
[2025-07-20T10:45:30.928+0000] {logging_mixin.py:188} INFO - ‚úÖ Accuracy:  0.7787
[2025-07-20T10:45:30.928+0000] {logging_mixin.py:188} INFO - ‚úÖ Precision: 0.7205
[2025-07-20T10:45:30.929+0000] {logging_mixin.py:188} INFO - ‚úÖ Recall:    0.6952
[2025-07-20T10:45:30.930+0000] {logging_mixin.py:188} INFO - ‚úÖ F1-score:  0.7076
[2025-07-20T10:45:30.930+0000] {logging_mixin.py:188} INFO - ‚úÖ AUC-ROC:   0.7755
[2025-07-20T10:45:31.041+0000] {connectionpool.py:868} WARNING - Retrying (Retry(total=4, connect=4, read=5, redirect=5, status=5)) after connection broken by 'NewConnectionError('<urllib3.connection.HTTPConnection object at 0x7a5e0a6713a0>: Failed to establish a new connection: [Errno 111] Connection refused')': /api/2.0/mlflow/experiments/get-by-name?experiment_name=Lead_Conversion_Classification
[2025-07-20T10:45:35.231+0000] {connectionpool.py:868} WARNING - Retrying (Retry(total=3, connect=3, read=5, redirect=5, status=5)) after connection broken by 'NewConnectionError('<urllib3.connection.HTTPConnection object at 0x7a5e0a671c70>: Failed to establish a new connection: [Errno 111] Connection refused')': /api/2.0/mlflow/experiments/get-by-name?experiment_name=Lead_Conversion_Classification
[2025-07-20T10:45:44.243+0000] {connectionpool.py:868} WARNING - Retrying (Retry(total=2, connect=2, read=5, redirect=5, status=5)) after connection broken by 'NewConnectionError('<urllib3.connection.HTTPConnection object at 0x7a5e0a6712e0>: Failed to establish a new connection: [Errno 111] Connection refused')': /api/2.0/mlflow/experiments/get-by-name?experiment_name=Lead_Conversion_Classification
[2025-07-20T10:46:00.527+0000] {connectionpool.py:868} WARNING - Retrying (Retry(total=1, connect=1, read=5, redirect=5, status=5)) after connection broken by 'NewConnectionError('<urllib3.connection.HTTPConnection object at 0x7a5e0a669790>: Failed to establish a new connection: [Errno 111] Connection refused')': /api/2.0/mlflow/experiments/get-by-name?experiment_name=Lead_Conversion_Classification
[2025-07-20T10:46:32.852+0000] {connectionpool.py:868} WARNING - Retrying (Retry(total=0, connect=0, read=5, redirect=5, status=5)) after connection broken by 'NewConnectionError('<urllib3.connection.HTTPConnection object at 0x7a5e0a83c730>: Failed to establish a new connection: [Errno 111] Connection refused')': /api/2.0/mlflow/experiments/get-by-name?experiment_name=Lead_Conversion_Classification
[2025-07-20T10:46:32.856+0000] {taskinstance.py:2698} ERROR - Task failed with exception
Traceback (most recent call last):
  File "/home/airflow/.local/lib/python3.9/site-packages/urllib3/connection.py", line 198, in _new_conn
    sock = connection.create_connection(
  File "/home/airflow/.local/lib/python3.9/site-packages/urllib3/util/connection.py", line 85, in create_connection
    raise err
  File "/home/airflow/.local/lib/python3.9/site-packages/urllib3/util/connection.py", line 73, in create_connection
    sock.connect(sa)
ConnectionRefusedError: [Errno 111] Connection refused

The above exception was the direct cause of the following exception:

Traceback (most recent call last):
  File "/home/airflow/.local/lib/python3.9/site-packages/urllib3/connectionpool.py", line 787, in urlopen
    response = self._make_request(
  File "/home/airflow/.local/lib/python3.9/site-packages/urllib3/connectionpool.py", line 493, in _make_request
    conn.request(
  File "/home/airflow/.local/lib/python3.9/site-packages/urllib3/connection.py", line 494, in request
    self.endheaders()
  File "/usr/local/lib/python3.9/http/client.py", line 1280, in endheaders
    self._send_output(message_body, encode_chunked=encode_chunked)
  File "/usr/local/lib/python3.9/http/client.py", line 1040, in _send_output
    self.send(msg)
  File "/usr/local/lib/python3.9/http/client.py", line 980, in send
    self.connect()
  File "/home/airflow/.local/lib/python3.9/site-packages/urllib3/connection.py", line 325, in connect
    self.sock = self._new_conn()
  File "/home/airflow/.local/lib/python3.9/site-packages/urllib3/connection.py", line 213, in _new_conn
    raise NewConnectionError(
urllib3.exceptions.NewConnectionError: <urllib3.connection.HTTPConnection object at 0x7a5e0a83c640>: Failed to establish a new connection: [Errno 111] Connection refused

The above exception was the direct cause of the following exception:

Traceback (most recent call last):
  File "/home/airflow/.local/lib/python3.9/site-packages/requests/adapters.py", line 667, in send
    resp = conn.urlopen(
  File "/home/airflow/.local/lib/python3.9/site-packages/urllib3/connectionpool.py", line 871, in urlopen
    return self.urlopen(
  File "/home/airflow/.local/lib/python3.9/site-packages/urllib3/connectionpool.py", line 871, in urlopen
    return self.urlopen(
  File "/home/airflow/.local/lib/python3.9/site-packages/urllib3/connectionpool.py", line 871, in urlopen
    return self.urlopen(
  [Previous line repeated 2 more times]
  File "/home/airflow/.local/lib/python3.9/site-packages/urllib3/connectionpool.py", line 841, in urlopen
    retries = retries.increment(
  File "/home/airflow/.local/lib/python3.9/site-packages/urllib3/util/retry.py", line 519, in increment
    raise MaxRetryError(_pool, url, reason) from reason  # type: ignore[arg-type]
urllib3.exceptions.MaxRetryError: HTTPConnectionPool(host='127.0.0.1', port=5000): Max retries exceeded with url: /api/2.0/mlflow/experiments/get-by-name?experiment_name=Lead_Conversion_Classification (Caused by NewConnectionError('<urllib3.connection.HTTPConnection object at 0x7a5e0a83c640>: Failed to establish a new connection: [Errno 111] Connection refused'))

During handling of the above exception, another exception occurred:

Traceback (most recent call last):
  File "/home/airflow/.local/lib/python3.9/site-packages/mlflow/utils/rest_utils.py", line 107, in http_request
    return _get_http_response_with_retries(
  File "/home/airflow/.local/lib/python3.9/site-packages/mlflow/utils/request_utils.py", line 197, in _get_http_response_with_retries
    return session.request(method, url, allow_redirects=allow_redirects, **kwargs)
  File "/home/airflow/.local/lib/python3.9/site-packages/requests/sessions.py", line 589, in request
    resp = self.send(prep, **send_kwargs)
  File "/home/airflow/.local/lib/python3.9/site-packages/requests/sessions.py", line 703, in send
    r = adapter.send(request, **kwargs)
  File "/home/airflow/.local/lib/python3.9/site-packages/requests/adapters.py", line 700, in send
    raise ConnectionError(e, request=request)
requests.exceptions.ConnectionError: HTTPConnectionPool(host='127.0.0.1', port=5000): Max retries exceeded with url: /api/2.0/mlflow/experiments/get-by-name?experiment_name=Lead_Conversion_Classification (Caused by NewConnectionError('<urllib3.connection.HTTPConnection object at 0x7a5e0a83c640>: Failed to establish a new connection: [Errno 111] Connection refused'))

During handling of the above exception, another exception occurred:

Traceback (most recent call last):
  File "/home/airflow/.local/lib/python3.9/site-packages/airflow/models/taskinstance.py", line 433, in _execute_task
    result = execute_callable(context=context, **execute_callable_kwargs)
  File "/home/airflow/.local/lib/python3.9/site-packages/airflow/operators/python.py", line 199, in execute
    return_value = self.execute_callable()
  File "/home/airflow/.local/lib/python3.9/site-packages/airflow/operators/python.py", line 216, in execute_callable
    return self.python_callable(*self.op_args, **self.op_kwargs)
  File "/opt/airflow/dags/retrain_model_dag.py", line 10, in retrain_model
    main()
  File "/opt/airflow/dags/main.py", line 182, in main
    mlflow_run_with_grid_search(X_train, X_test, y_train, y_test, model_registry)
  File "/opt/airflow/src/mlflow_runner.py", line 139, in mlflow_run_with_grid_search
    mlflow.set_experiment("Lead_Conversion_Classification")
  File "/home/airflow/.local/lib/python3.9/site-packages/mlflow/tracking/fluent.py", line 135, in set_experiment
    experiment = client.get_experiment_by_name(experiment_name)
  File "/home/airflow/.local/lib/python3.9/site-packages/mlflow/tracking/client.py", line 520, in get_experiment_by_name
    return self._tracking_client.get_experiment_by_name(name)
  File "/home/airflow/.local/lib/python3.9/site-packages/mlflow/tracking/_tracking_service/client.py", line 221, in get_experiment_by_name
    return self.store.get_experiment_by_name(name)
  File "/home/airflow/.local/lib/python3.9/site-packages/mlflow/store/tracking/rest_store.py", line 306, in get_experiment_by_name
    response_proto = self._call_endpoint(GetExperimentByName, req_body)
  File "/home/airflow/.local/lib/python3.9/site-packages/mlflow/store/tracking/rest_store.py", line 59, in _call_endpoint
    return call_endpoint(self.get_host_creds(), endpoint, method, json_body, response_proto)
  File "/home/airflow/.local/lib/python3.9/site-packages/mlflow/utils/rest_utils.py", line 215, in call_endpoint
    response = http_request(**call_kwargs)
  File "/home/airflow/.local/lib/python3.9/site-packages/mlflow/utils/rest_utils.py", line 129, in http_request
    raise MlflowException(f"API request to {url} failed with exception {e}")
mlflow.exceptions.MlflowException: API request to http://127.0.0.1:5000/api/2.0/mlflow/experiments/get-by-name failed with exception HTTPConnectionPool(host='127.0.0.1', port=5000): Max retries exceeded with url: /api/2.0/mlflow/experiments/get-by-name?experiment_name=Lead_Conversion_Classification (Caused by NewConnectionError('<urllib3.connection.HTTPConnection object at 0x7a5e0a83c640>: Failed to establish a new connection: [Errno 111] Connection refused'))
[2025-07-20T10:46:32.977+0000] {taskinstance.py:1138} INFO - Marking task as FAILED. dag_id=retrain_model_dag, task_id=retrain_best_model, execution_date=20250720T104458, start_date=20250720T104514, end_date=20250720T104632
[2025-07-20T10:46:33.111+0000] {standard_task_runner.py:107} ERROR - Failed to execute job 61 for task retrain_best_model (API request to http://127.0.0.1:5000/api/2.0/mlflow/experiments/get-by-name failed with exception HTTPConnectionPool(host='127.0.0.1', port=5000): Max retries exceeded with url: /api/2.0/mlflow/experiments/get-by-name?experiment_name=Lead_Conversion_Classification (Caused by NewConnectionError('<urllib3.connection.HTTPConnection object at 0x7a5e0a83c640>: Failed to establish a new connection: [Errno 111] Connection refused')); 127)
[2025-07-20T10:46:33.145+0000] {local_task_job_runner.py:234} INFO - Task exited with return code 1
[2025-07-20T10:46:33.195+0000] {taskinstance.py:3280} INFO - 0 downstream tasks scheduled from follow-on schedule check
