[2025-07-19T06:22:00.860+0000] {taskinstance.py:1956} INFO - Dependencies all met for dep_context=non-requeueable deps ti=<TaskInstance: drift_detection_dag.decide_drift_action manual__2025-07-19T06:21:55.902919+00:00 [queued]>
[2025-07-19T06:22:00.871+0000] {taskinstance.py:1956} INFO - Dependencies all met for dep_context=requeueable deps ti=<TaskInstance: drift_detection_dag.decide_drift_action manual__2025-07-19T06:21:55.902919+00:00 [queued]>
[2025-07-19T06:22:00.872+0000] {taskinstance.py:2170} INFO - Starting attempt 1 of 2
[2025-07-19T06:22:00.994+0000] {taskinstance.py:2191} INFO - Executing <Task(BranchPythonOperator): decide_drift_action> on 2025-07-19 06:21:55.902919+00:00
[2025-07-19T06:22:00.999+0000] {standard_task_runner.py:60} INFO - Started process 79 to run task
[2025-07-19T06:22:01.007+0000] {standard_task_runner.py:87} INFO - Running: ['airflow', 'tasks', 'run', 'drift_detection_dag', 'decide_drift_action', 'manual__2025-07-19T06:21:55.902919+00:00', '--job-id', '9', '--raw', '--subdir', 'DAGS_FOLDER/drift_detection_dag.py', '--cfg-path', '/tmp/tmp7id27jk9']
[2025-07-19T06:22:01.009+0000] {standard_task_runner.py:88} INFO - Job 9: Subtask decide_drift_action
[2025-07-19T06:22:01.109+0000] {task_command.py:423} INFO - Running <TaskInstance: drift_detection_dag.decide_drift_action manual__2025-07-19T06:21:55.902919+00:00 [running]> on host 6db25d098dfe
[2025-07-19T06:22:01.266+0000] {taskinstance.py:2480} INFO - Exporting env vars: AIRFLOW_CTX_DAG_OWNER='airflow' AIRFLOW_CTX_DAG_ID='drift_detection_dag' AIRFLOW_CTX_TASK_ID='decide_drift_action' AIRFLOW_CTX_EXECUTION_DATE='2025-07-19T06:21:55.902919+00:00' AIRFLOW_CTX_TRY_NUMBER='1' AIRFLOW_CTX_DAG_RUN_ID='manual__2025-07-19T06:21:55.902919+00:00'
[2025-07-19T06:22:01.272+0000] {taskinstance.py:2698} ERROR - Task failed with exception
Traceback (most recent call last):
  File "/home/airflow/.local/lib/python3.9/site-packages/airflow/models/taskinstance.py", line 433, in _execute_task
    result = execute_callable(context=context, **execute_callable_kwargs)
  File "/home/airflow/.local/lib/python3.9/site-packages/airflow/operators/python.py", line 233, in execute
    return self.do_branch(context, super().execute(context))
  File "/home/airflow/.local/lib/python3.9/site-packages/airflow/operators/python.py", line 199, in execute
    return_value = self.execute_callable()
  File "/home/airflow/.local/lib/python3.9/site-packages/airflow/operators/python.py", line 216, in execute_callable
    return self.python_callable(*self.op_args, **self.op_kwargs)
  File "/opt/airflow/dags/drift_detection_dag.py", line 109, in check_drift_flag
    with open(DRIFT_LOG_PATH, 'a') as log:
FileNotFoundError: [Errno 2] No such file or directory: 'airflow/dags/drift_detected_log.txt'
[2025-07-19T06:22:01.282+0000] {taskinstance.py:1138} INFO - Marking task as UP_FOR_RETRY. dag_id=drift_detection_dag, task_id=decide_drift_action, execution_date=20250719T062155, start_date=20250719T062200, end_date=20250719T062201
[2025-07-19T06:22:01.326+0000] {standard_task_runner.py:107} ERROR - Failed to execute job 9 for task decide_drift_action ([Errno 2] No such file or directory: 'airflow/dags/drift_detected_log.txt'; 79)
[2025-07-19T06:22:01.341+0000] {local_task_job_runner.py:234} INFO - Task exited with return code 1
[2025-07-19T06:22:01.407+0000] {taskinstance.py:3280} INFO - 0 downstream tasks scheduled from follow-on schedule check
