[2025-07-19T16:34:41.722+0000] {taskinstance.py:1956} INFO - Dependencies all met for dep_context=non-requeueable deps ti=<TaskInstance: retrain_model_dag.retrain_best_model manual__2025-07-19T16:34:33.737958+00:00 [queued]>
[2025-07-19T16:34:41.752+0000] {taskinstance.py:1956} INFO - Dependencies all met for dep_context=requeueable deps ti=<TaskInstance: retrain_model_dag.retrain_best_model manual__2025-07-19T16:34:33.737958+00:00 [queued]>
[2025-07-19T16:34:41.753+0000] {taskinstance.py:2170} INFO - Starting attempt 1 of 1
[2025-07-19T16:34:41.982+0000] {taskinstance.py:2191} INFO - Executing <Task(PythonOperator): retrain_best_model> on 2025-07-19 16:34:33.737958+00:00
[2025-07-19T16:34:41.996+0000] {standard_task_runner.py:60} INFO - Started process 61 to run task
[2025-07-19T16:34:42.007+0000] {standard_task_runner.py:87} INFO - Running: ['airflow', 'tasks', 'run', 'retrain_model_dag', 'retrain_best_model', 'manual__2025-07-19T16:34:33.737958+00:00', '--job-id', '39', '--raw', '--subdir', 'DAGS_FOLDER/retrain_model_dag.py', '--cfg-path', '/tmp/tmpekeeodrz']
[2025-07-19T16:34:42.013+0000] {standard_task_runner.py:88} INFO - Job 39: Subtask retrain_best_model
[2025-07-19T16:34:42.186+0000] {task_command.py:423} INFO - Running <TaskInstance: retrain_model_dag.retrain_best_model manual__2025-07-19T16:34:33.737958+00:00 [running]> on host 5ce9d8b5274e
[2025-07-19T16:34:42.369+0000] {taskinstance.py:2480} INFO - Exporting env vars: AIRFLOW_CTX_DAG_OWNER='airflow' AIRFLOW_CTX_DAG_ID='retrain_model_dag' AIRFLOW_CTX_TASK_ID='retrain_best_model' AIRFLOW_CTX_EXECUTION_DATE='2025-07-19T16:34:33.737958+00:00' AIRFLOW_CTX_TRY_NUMBER='1' AIRFLOW_CTX_DAG_RUN_ID='manual__2025-07-19T16:34:33.737958+00:00'
[2025-07-19T16:34:42.370+0000] {logging_mixin.py:188} INFO - üì¶ Starting retraining process
[2025-07-19T16:34:42.371+0000] {logging_mixin.py:188} INFO - üóÑÔ∏è Loading data...
[2025-07-19T16:34:42.383+0000] {taskinstance.py:2698} ERROR - Task failed with exception
Traceback (most recent call last):
  File "/home/airflow/.local/lib/python3.9/site-packages/airflow/models/taskinstance.py", line 433, in _execute_task
    result = execute_callable(context=context, **execute_callable_kwargs)
  File "/home/airflow/.local/lib/python3.9/site-packages/airflow/operators/python.py", line 199, in execute
    return_value = self.execute_callable()
  File "/home/airflow/.local/lib/python3.9/site-packages/airflow/operators/python.py", line 216, in execute_callable
    return self.python_callable(*self.op_args, **self.op_kwargs)
  File "/opt/airflow/dags/retrain_model_dag.py", line 10, in retrain_model
    main()
  File "/opt/airflow/dags/main.py", line 134, in main
    df = pd.read_csv("data/raw/Lead Scoring.csv")
  File "/home/airflow/.local/lib/python3.9/site-packages/pandas/io/parsers/readers.py", line 948, in read_csv
    return _read(filepath_or_buffer, kwds)
  File "/home/airflow/.local/lib/python3.9/site-packages/pandas/io/parsers/readers.py", line 611, in _read
    parser = TextFileReader(filepath_or_buffer, **kwds)
  File "/home/airflow/.local/lib/python3.9/site-packages/pandas/io/parsers/readers.py", line 1448, in __init__
    self._engine = self._make_engine(f, self.engine)
  File "/home/airflow/.local/lib/python3.9/site-packages/pandas/io/parsers/readers.py", line 1705, in _make_engine
    self.handles = get_handle(
  File "/home/airflow/.local/lib/python3.9/site-packages/pandas/io/common.py", line 863, in get_handle
    handle = open(
FileNotFoundError: [Errno 2] No such file or directory: 'data/raw/Lead Scoring.csv'
[2025-07-19T16:34:42.405+0000] {taskinstance.py:1138} INFO - Marking task as FAILED. dag_id=retrain_model_dag, task_id=retrain_best_model, execution_date=20250719T163433, start_date=20250719T163441, end_date=20250719T163442
[2025-07-19T16:34:42.451+0000] {standard_task_runner.py:107} ERROR - Failed to execute job 39 for task retrain_best_model ([Errno 2] No such file or directory: 'data/raw/Lead Scoring.csv'; 61)
[2025-07-19T16:34:42.463+0000] {local_task_job_runner.py:234} INFO - Task exited with return code 1
[2025-07-19T16:34:42.487+0000] {taskinstance.py:3280} INFO - 0 downstream tasks scheduled from follow-on schedule check
